<?xml version="1.0"?>
<robot
  xmlns:xacro="http://www.ros.org/wiki/xacro"
  name="wheel">

  <xacro:property name="wheel_radius" value="0.0352" />
  <xacro:property name="wheel_width" value="0.0206" />
  <xacro:property name="wheel_mass" value="0.2" />
  <xacro:property name="M_PI" value="3.14159265359" />

  <xacro:macro name="drive_wheel" params="side parent robot_name *origin">
    <link name="${robot_name}/${side}_wheel">
      <visual>
        <origin rpy="0 ${M_PI/2} ${M_PI/2}" xyz="0 0 0" />
        <geometry>
          <cylinder length="${wheel_width}" radius="${wheel_radius}" />
        </geometry>
        <material name="black" />
      </visual>
      <collision>
        <origin rpy="0 ${M_PI/2} ${M_PI/2}" xyz="0 0 0" />
        <geometry>
          <cylinder length="${wheel_width}" radius="${wheel_radius}" />
        </geometry>
      </collision>
      <inertial>
        <origin rpy="0 0 0" xyz="0 0 0" />
        <mass value="${wheel_mass}" />
        <inertia
          ixx="0.0001"
          iyy="0.0001"
          izz="0.0002"
          ixy="0.0"
          ixz="0.0"
          iyz="0.0" />
      </inertial>
    </link>
    <joint name="${robot_name}/joint_${side}_wheel" type="continuous">
      <xacro:insert_block name="origin" />
      <child link="${robot_name}/${side}_wheel" />
      <parent link="${parent}" />
      <axis rpy="0 0 0" xyz="0 1 0" />
      <limit effort="10000" velocity="1000" />
      <joint_properties damping="1.0" friction="1.0" />
    </joint>
  </xacro:macro>
</robot>
